Workbook
Name Departments: "GE,IT,ENG,BM,HRM,THM,AS"
Name SHS1FIELD: '[1]3.3 - SHS Term 1 '!$E$4:$E$255
Name SHS1FIELD: '[2]3.3 - SHS Term 1 '!$E$4:$E$255
Name SHS1FIELD: '3.3 - SHS Term 1 '!$E$3:$E$254
Name SHS1LOAD: '[1]3.3 - SHS Term 1 '!$I$4:$I$255
Name SHS1LOAD: '[2]3.3 - SHS Term 1 '!$I$4:$I$255
Name SHS1LOAD: '3.3 - SHS Term 1 '!$I$3:$I$254
Name SHS2FIELD: '[1]3.4 - SHS Term 2'!$E$4:$E$255
Name SHS2FIELD: '[2]3.4 - SHS Term 2'!$E$4:$E$255
Name SHS2FIELD: '3.4 - SHS Term 2'!$E$3:$E$254
Name SHS2LOAD: '[3]3.4 - SHS Term 2'!$I$4:$I$255
Name SHS2LOAD: '[1]3.4 - SHS Term 2'!$I$4:$I$255
Name SHS2LOAD: '[1]3.4 - SHS Term 2'!$I$4:$I$255
Name SHS2LOAD: '[2]3.4 - SHS Term 2'!$I$4:$I$255
Name SHS2LOAD: '3.4 - SHS Term 2'!$I$3:$I$254
Name TER1FIELD: '[1]3.1 - Tertiary - Term 1'!$E$4:$E$653
Name TER1FIELD: '[2]3.1 - Tertiary - Term 1'!$E$4:$E$653
Name TER1FIELD: '3.1 - Tertiary - Term 1'!$E$3:$E$659
Name TER1LOAD: '[1]3.1 - Tertiary - Term 1'!$J$4:$J$653
Name TER1LOAD: '[2]3.1 - Tertiary - Term 1'!$J$4:$J$653
Name TER1LOAD: '3.1 - Tertiary - Term 1'!$J$3:$J$659
Name TER2FIELD: '[1]3.2 - Tertiary - Term 2'!$E$4:$E$571
Name TER2FIELD: '[1]3.2 - Tertiary - Term 2'!$E$4:$E$571
Name TER2FIELD: '[2]3.2 - Tertiary - Term 2'!$E$4:$E$571
Name TER2FIELD: '3.2 - Tertiary - Term 2'!$E$3:$E$588
Name TER2LOAD: '[3]3.2 - Tertiary - Term 2'!$J$4:$J$571
Name TER2LOAD: '[1]3.2 - Tertiary - Term 2'!$J$4:$J$571
Name TER2LOAD: '[1]3.2 - Tertiary - Term 2'!$J$4:$J$571
Name TER2LOAD: '[2]3.2 - Tertiary - Term 2'!$J$4:$J$571
Name TER2LOAD: '3.2 - Tertiary - Term 2'!$J$3:$J$588
Name ThuRooms: [1]THURSDAY!$C$4:$BK$31
Name Thursday: [1]THURSDAY!$C$3:$BK$3
Name TIME: '[3]<Day 1>'!$A$4:$A$31
Name TIME: [1]MONDAY!$A$4:$A$31
Name TIME: [1]MONDAY!$A$4:$A$31
Name TIME: FRIDAY!$A$4:$A$31
Name TIME: [2]MONDAY!$A$4:$A$31
Name TIME: SATURDAY!$A$4:$A$31
Name TIME: THURSDAY!$A$4:$A$31
Name TIME: TUESDAY!$A$4:$A$31
Name TIME: WEDNESDAY!$A$4:$A$31
Name TIME: MONDAY!$A$4:$A$31
Name TueRooms: [1]TUESDAY!$C$4:$BK$31
Name Tuesday: [1]TUESDAY!$C$3:$BK$3
Name Wednesday: [1]WEDNESDAY!$C$3:$BK$3
Name WedRooms: [1]WEDNESDAY!$C$4:$BK$31

Sheet 1 - Top Sheet
B6: STI | D6: Novaliches | F6: <-- indicate Campus
B7: School Year | D7: 2024-2025 | F7: <-- indicate School Year
B8: Term | D8: 1 | F8: <-- indicate Term
B10: Section Count Projection | H10: Projected Faculty Count: Tertiary | N10: Projected Faculty Count: High School | T10: Room Projections
D12: Class Density | E12: Projected NS/OS | F12: Section Count | K12: Full-time FM | L12: Excess Units | Q12: Full-time FM | R12: Excess Units | T12: Lecture Rooms
B13: Highschool | D13: ='2 - Section Count Projection'!D5 -> 40 | E13: ='2 - Section Count Projection'!F71 -> 0 | F13: ='2 - Section Count Projection'!G71 -> 0 | H13: Information & Communication Tech. | K13: ='Faculty Count Projection'!E14+'Faculty Count Projection'!E16+'Faculty Count Projection'!E20 -> 16 | L13: ='Faculty Count Projection'!F14+'Faculty Count Projection'!F16+'Faculty Count Projection'!F20 -> 18.5 | N13: Business and Management | Q13: ='Faculty Count Projection'!K9 -> 1 | R13: ='Faculty Count Projection'!L9 -> 12
B14: 4-Year Degree | D14: ='2 - Section Count Projection'!L5 -> 40 | E14: ='2 - Section Count Projection'!N162 -> 0 | F14: ='2 - Section Count Projection'!O162 -> 0 | H14: Business and Management | K14: ='Faculty Count Projection'!E9+'Faculty Count Projection'!E11+'Faculty Count Projection'!E21 -> 1 | L14: ='Faculty Count Projection'!F9+'Faculty Count Projection'!F11+'Faculty Count Projection'!F21 -> 4.5 | N14: Electrical/Electronics | Q14: ='Faculty Count Projection'!K10 -> 0 | R14: ='Faculty Count Projection'!L10 -> 0 | T14: Available Lecture Sessions | V14: ='Room Utilization Efficiency'!$I$51 -> 2808
B15: 2-Year Degree | D15: ='2 - Section Count Projection'!D75 -> 0 | E15: ='2 - Section Count Projection'!F107 -> 0 | F15: ='2 - Section Count Projection'!G107 -> 0 | H15: Tourism & Hospitality Management | K15: ='Faculty Count Projection'!E19+'Faculty Count Projection'!E29 -> 4 | L15: ='Faculty Count Projection'!F19+'Faculty Count Projection'!F29 -> 18 | N15: English | Q15: ='Faculty Count Projection'!K11 -> 6 | R15: ='Faculty Count Projection'!L11 -> 6 | T15: Projected Lecture Sessions | V15: ='Room Utilization Efficiency'!$I$52 -> 973
F16: =SUM(F13:F15) -> 0 | H16: General Education | K16: ='Faculty Count Projection'!E10+'Faculty Count Projection'!E12+'Faculty Count Projection'!E15+'Faculty Count Projection'!E17+'Faculty Count Projection'!E18+'Faculty Count Projection'!E22+'Faculty Count Projection'!E25+'Faculty Count Projection'!E26+'Faculty Count Projection'!E27+'Faculty Count Projection'!E28 -> 14 | L16: ='Faculty Count Projection'!F10+'Faculty Count Projection'!F12+'Faculty Count Projection'!F15+'Faculty Count Projection'!F17+'Faculty Count Projection'!F18+'Faculty Count Projection'!F22+'Faculty Count Projection'!F25+'Faculty Count Projection'!F26+'Faculty Count Projection'!F27+'Faculty Count Projection'!F28 -> 53 | N16: Filipino | Q16: ='Faculty Count Projection'!K12 -> 3 | R16: ='Faculty Count Projection'!L12 -> 21
H17: Arts & Sciences | K17: ='Faculty Count Projection'!E23 -> 6 | L17: ='Faculty Count Projection'!F23 -> 9.5 | N17: Hospitality/Culinary Mgt | Q17: ='Faculty Count Projection'!K13 -> 0 | R17: ='Faculty Count Projection'!L13 -> 24 | T17: Computer Laboratory
K18: =SUM(K13:K17) -> 41 | L18: =SUM(L13:L17) -> 103.5 | N18: Information Technology | Q18: ='Faculty Count Projection'!K14 -> 1 | R18: ='Faculty Count Projection'!L14 -> 9
I19: *For a more detailed breakdown refer to the faculty count projection sheet | N19: Mathematics | Q19: ='Faculty Count Projection'!K15 -> 3 | R19: ='Faculty Count Projection'!L15 -> 12 | T19: Available Lab Sessions | V19: ='5 - Computer Lab'!$L$4 -> 120
N20: Physical Education | Q20: ='Faculty Count Projection'!K16 -> 4 | R20: ='Faculty Count Projection'!L16 -> 21 | T20: Projected Lab Sessions | V20: ='5 - Computer Lab'!$L$6 -> 205
N21: Sciences | Q21: ='Faculty Count Projection'!K17 -> 4 | R21: ='Faculty Count Projection'!L17 -> 6
N22: Social and Behavioral Sciences | Q22: ='Faculty Count Projection'!K18 -> 7 | R22: ='Faculty Count Projection'!L18 -> 18 | T22: Culinary Laboratory
N23: Tourism Management | Q23: ='Faculty Count Projection'!K19 -> 0 | R23: ='Faculty Count Projection'!L19 -> 24
Q24: =SUM(Q13:Q23) -> 29 | R24: =SUM(R13:R23) -> 153 | T24: Available Lab Sessions | V24: ='6 - Culinary Lab '!$L$4 -> 0
T25: Projected Lab Sessions | V25: ='6 - Culinary Lab '!$L$6 -> 0
T27: Room Utilization
T29: Lecture Rooms | V29: ='Room Utilization Efficiency'!$I$50 -> 1
T30: Laboratories | V30: ='Room Utilization Efficiency'!$R$19 -> 1

Sheet 2 - Section Count Projection
B1: =_xlfn.CONCAT("STI College ",'1 - Top Sheet'!D6:E6) -> STI College Novaliches
B2: Section Count Projection
B3: =_xlfn.CONCAT("School Year ",'1 - Top Sheet'!D7:E7," Term ", '1 - Top Sheet'!D8:E8) -> School Year 2024-2025 Term 1
B4: High School Programs | J4: 4-Year Degree Programs
C5: Class Density | D5: 40 | K5: Class Density | L5: 40
B7: Instruction: Fill-out only the GREEN cells
E8: =B3 -> School Year 2024-2025 Term 1 | M8: =B3 -> School Year 2024-2025 Term 1
B9: Track / Strand | C9: Year Level Term | D9: Current OGS | E9: Year Level Term | F9: Projected NS /OS | G9: Section Count | H9: Remarks | J9: Program | K9: Year Level Term | L9: Current OS | M9: Year Level Term | N9: Projected NS / OS | O9: Section Count | P9: Remarks
B11: Junior High School | C11: 7 | G11: =IF($D$5=0,0,IF(AND(F11>0,F11-$D$5<6),ROUNDUP((F11-5)/$D$5,0),ROUNDUP(F11/$D$5,0))) -> 0 | H11: =IF(AND(F11<$D$5,F11>0),"can be merged","") | J11: BS in Information Techology (BSIT) | K11: 1-1 | M11: 1-1 | O11: =IF($L$5=0,0,IF(AND(N11>0,N11-$L$5<6),ROUNDUP((N11-5)/$L$5,0),ROUNDUP(N11/$L$5,0))) -> 0 | P11: =IF(AND(N11<$L$5,N11>0),"can be merged","")
B12: Retention Rate: | C12: 8 | E12: 8 | F12: =ROUNDUP((F11*$B$13)*$B$15,0) -> 0 | G12: =IF($D$5=0,0,IF(AND(F12>0,F12-$D$5<6),ROUNDUP((F12-5)/$D$5,0),ROUNDUP(F12/$D$5,0))) -> 0 | H12: =IF(AND(F12<$D$5,F12>0),"can be merged","") | K12: 1-2 | M12: 1-2 | N12: =IF(L11<>"",ROUNDUP((L11*$J$15)*$J$17,0),0) -> 0 | O12: =IF($L$5=0,0,IF(AND(N12>0,N12-$L$5<6),ROUNDUP((N12-5)/$L$5,0),ROUNDUP(N12/$L$5,0))) -> 0 | P12: =IF(AND(N12<$L$5,N12>0),"can be merged","")
C13: 9 | E13: 9 | F13: =ROUNDUP((D12*$B$13)*$B$15,0) -> 0 | G13: =IF($D$5=0,0,IF(AND(F13>0,F13-$D$5<6),ROUNDUP((F13-5)/$D$5,0),ROUNDUP(F13/$D$5,0))) -> 0 | H13: =IF(AND(F13<$D$5,F13>0),"can be merged","") | K13: 2-1 | M13: 2-1 | N13: =IF(L12<>"",ROUNDUP((L12*$J$15)*$J$17,0),0) -> 0 | O13: =IF($L$5=0,0,IF(AND(N13>0,N13-$L$5<6),ROUNDUP((N13-5)/$L$5,0),ROUNDUP(N13/$L$5,0))) -> 0 | P13: =IF(AND(N13<$L$5,N13>0),"can be merged","")
B14: Migration Rate: | C14: 10 | E14: 10 | F14: =ROUNDUP((D13*$B$13)*$B$15,0) -> 0 | G14: =IF($D$5=0,0,IF(AND(F14>0,F14-$D$5<6),ROUNDUP((F14-5)/$D$5,0),ROUNDUP(F14/$D$5,0))) -> 0 | H14: =IF(AND(F14<$D$5,F14>0),"can be merged","") | J14: Retention Rate: | K14: 2-2 | M14: 2-2 | N14: =IF(L13<>"",ROUNDUP((L13*$J$15)*$J$17,0),0) -> 0 | O14: =IF($L$5=0,0,IF(AND(N14>0,N14-$L$5<6),ROUNDUP((N14-5)/$L$5,0),ROUNDUP(N14/$L$5,0))) -> 0 | P14: =IF(AND(N14<$L$5,N14>0),"can be merged","")
C15: Total | F15: =SUM(F11:F14) -> 0 | G15: =SUM(G11:G14) -> 0 | J15: 0.95 | K15: 3-1 | M15: 3-1 | N15: =IF(L14<>"",ROUNDUP((L14*$J$15)*$J$17,0),0) -> 0 | O15: =IF($L$5=0,0,IF(AND(N15>0,N15-$L$5<6),ROUNDUP((N15-5)/$L$5,0),ROUNDUP(N15/$L$5,0))) -> 0 | P15: =IF(AND(N15<$L$5,N15>0),"can be merged","")
B16: STEM | C16: 11-1 | E16: 11-1 | G16: =IF($D$5=0,0,IF(AND(F16>0,F16-$D$5<6),ROUNDUP((F16-5)/$D$5,0),ROUNDUP(F16/$D$5,0))) -> 0 | H16: =IF(AND(F16<$D$5,F16>0),"can be merged","") | J16: Migration Rate: | K16: 3-2 | M16: 3-2 | N16: =IF(L15<>"",ROUNDUP((L15*$J$15)*$J$17,0),0) -> 0 | O16: =IF($L$5=0,0,IF(AND(N16>0,N16-$L$5<6),ROUNDUP((N16-5)/$L$5,0),ROUNDUP(N16/$L$5,0))) -> 0 | P16: =IF(AND(N16<$L$5,N16>0),"can be merged","")
B17: Retention Rate: | C17: 11-2 | E17: 11-2 | F17: =ROUNDUP((D16*$B$18)*$B$20,0) -> 0 | G17: =IF($D$5=0,0,IF(AND(F17>0,F17-$D$5<6),ROUNDUP((F17-5)/$D$5,0),ROUNDUP(F17/$D$5,0))) -> 0 | H17: =IF(AND(F17<$D$5,F17>0),"can be merged","") | J17: 0.95 | K17: 4-1 | M17: 4-1 | N17: =IF(L16<>"",ROUNDUP((L16*$J$15)*$J$17,0),0) -> 0 | O17: =IF($L$5=0,0,IF(AND(N17>0,N17-$L$5<6),ROUNDUP((N17-5)/$L$5,0),ROUNDUP(N17/$L$5,0))) -> 0 | P17: =IF(AND(N17<$L$5,N17>0),"can be merged","")
C18: 12-1 | E18: 12-1 | F18: =ROUNDUP((D17*$B$18)*$B$20,0) -> 0 | G18: =IF($D$5=0,0,IF(AND(F18>0,F18-$D$5<6),ROUNDUP((F18-5)/$D$5,0),ROUNDUP(F18/$D$5,0))) -> 0 | H18: =IF(AND(F18<$D$5,F18>0),"can be merged","") | K18: 4-2 | M18: 4-2 | N18: =IF(L17<>"",ROUNDUP((L17*$J$15)*$J$17,0),0) -> 0 | O18: =IF($L$5=0,0,IF(AND(N18>0,N18-$L$5<6),ROUNDUP((N18-5)/$L$5,0),ROUNDUP(N18/$L$5,0))) -> 0 | P18: =IF(AND(N18<$L$5,N18>0),"can be merged","")
B19: Migration Rate: | C19: 12-2 | E19: 12-2 | F19: =ROUNDUP((D18*$B$18)*$B$20,0) -> 0 | G19: =IF($D$5=0,0,IF(AND(F19>0,F19-$D$5<6),ROUNDUP((F19-5)/$D$5,0),ROUNDUP(F19/$D$5,0))) -> 0 | H19: =IF(AND(F19<$D$5,F19>0),"can be merged","") | K19: Total | N19: =SUM(N11:N18) -> 0 | O19: =SUM(O11:O18) -> 0
C20: Total | F20: =SUM(F16:F19) -> 0 | G20: =SUM(G16:G19) -> 0 | J20: BS in Computer Science (BSCS) | K20: 1-1 | M20: 1-1 | O20: =IF($L$5=0,0,IF(AND(N20>0,N20-$L$5<6),ROUNDUP((N20-5)/$L$5,0),ROUNDUP(N20/$L$5,0))) -> 0 | P20: =IF(AND(N20<$L$5,N20>0),"can be merged","")
B21: ABM | C21: 11-1 | E21: 11-1 | G21: =IF($D$5=0,0,IF(AND(F21>0,F21-$D$5<6),ROUNDUP((F21-5)/$D$5,0),ROUNDUP(F21/$D$5,0))) -> 0 | H21: =IF(AND(F21<$D$5,F21>0),"can be merged","") | K21: 1-2 | M21: 1-2 | N21: =ROUNDUP((L20*$J$24)*$J$26,0) -> 0 | O21: =IF($L$5=0,0,IF(AND(N21>0,N21-$L$5<6),ROUNDUP((N21-5)/$L$5,0),ROUNDUP(N21/$L$5,0))) -> 0 | P21: =IF(AND(N21<$L$5,N21>0),"can be merged","")
B22: Retention Rate: | C22: 11-2 | E22: 11-2 | F22: =ROUNDUP((D21*$B$23)*$B$25,0) -> 0 | G22: =IF($D$5=0,0,IF(AND(F22>0,F22-$D$5<6),ROUNDUP((F22-5)/$D$5,0),ROUNDUP(F22/$D$5,0))) -> 0 | H22: =IF(AND(F22<$D$5,F22>0),"can be merged","") | K22: 2-1 | M22: 2-1 | N22: =ROUNDUP((L21*$J$24)*$J$26,0) -> 0 | O22: =IF($L$5=0,0,IF(AND(N22>0,N22-$L$5<6),ROUNDUP((N22-5)/$L$5,0),ROUNDUP(N22/$L$5,0))) -> 0 | P22: =IF(AND(N22<$L$5,N22>0),"can be merged","")
C23: 12-1 | E23: 12-1 | F23: =ROUNDUP((D22*$B$23)*$B$25,0) -> 0 | G23: =IF($D$5=0,0,IF(AND(F23>0,F23-$D$5<6),ROUNDUP((F23-5)/$D$5,0),ROUNDUP(F23/$D$5,0))) -> 0 | H23: =IF(AND(F23<$D$5,F23>0),"can be merged","") | J23: Retention Rate: | K23: 2-2 | M23: 2-2 | N23: =ROUNDUP((L22*$J$24)*$J$26,0) -> 0 | O23: =IF($L$5=0,0,IF(AND(N23>0,N23-$L$5<6),ROUNDUP((N23-5)/$L$5,0),ROUNDUP(N23/$L$5,0))) -> 0 | P23: =IF(AND(N23<$L$5,N23>0),"can be merged","")
B24: Migration Rate: | C24: 12-2 | E24: 12-2 | F24: =ROUNDUP((D23*$B$23)*$B$25,0) -> 0 | G24: =IF($D$5=0,0,IF(AND(F24>0,F24-$D$5<6),ROUNDUP((F24-5)/$D$5,0),ROUNDUP(F24/$D$5,0))) -> 0 | H24: =IF(AND(F24<$D$5,F24>0),"can be merged","") | K24: 3-1 | M24: 3-1 | N24: =ROUNDUP((L23*$J$24)*$J$26,0) -> 0 | O24: =IF($L$5=0,0,IF(AND(N24>0,N24-$L$5<6),ROUNDUP((N24-5)/$L$5,0),ROUNDUP(N24/$L$5,0))) -> 0 | P24: =IF(AND(N24<$L$5,N24>0),"can be merged","")
C25: Total | F25: =SUM(F21:F24) -> 0 | G25: =SUM(G21:G24) -> 0 | J25: Migration Rate: | K25: 3-2 | M25: 3-2 | N25: =ROUNDUP((L24*$J$24)*$J$26,0) -> 0 | O25: =IF($L$5=0,0,IF(AND(N25>0,N25-$L$5<6),ROUNDUP((N25-5)/$L$5,0),ROUNDUP(N25/$L$5,0))) -> 0 | P25: =IF(AND(N25<$L$5,N25>0),"can be merged","")
B26: General Academic (GA) | C26: 11-1 | E26: 11-1 | G26: =IF($D$5=0,0,IF(AND(F26>0,F26-$D$5<6),ROUNDUP((F26-5)/$D$5,0),ROUNDUP(F26/$D$5,0))) -> 0 | H26: =IF(AND(F26<$D$5,F26>0),"can be merged","") | K26: 4-1 | M26: 4-1 | N26: =ROUNDUP((L25*$J$24)*$J$26,0) -> 0 | O26: =IF($L$5=0,0,IF(AND(N26>0,N26-$L$5<6),ROUNDUP((N26-5)/$L$5,0),ROUNDUP(N26/$L$5,0))) -> 0 | P26: =IF(AND(N26<$L$5,N26>0),"can be merged","")
B27: Retention Rate: | C27: 11-2 | E27: 11-2 | F27: =ROUNDUP((D26*$B$28)*$B$30,0) -> 0 | G27: =IF($D$5=0,0,IF(AND(F27>0,F27-$D$5<6),ROUNDUP((F27-5)/$D$5,0),ROUNDUP(F27/$D$5,0))) -> 0 | H27: =IF(AND(F27<$D$5,F27>0),"can be merged","") | K27: 4-2 | M27: 4-2 | N27: =ROUNDUP((L26*$J$24)*$J$26,0) -> 0 | O27: =IF($L$5=0,0,IF(AND(N27>0,N27-$L$5<6),ROUNDUP((N27-5)/$L$5,0),ROUNDUP(N27/$L$5,0))) -> 0 | P27: =IF(AND(N27<$L$5,N27>0),"can be merged","")
C28: 12-1 | E28: 12-1 | F28: =ROUNDUP((D27*$B$28)*$B$30,0) -> 0 | G28: =IF($D$5=0,0,IF(AND(F28>0,F28-$D$5<6),ROUNDUP((F28-5)/$D$5,0),ROUNDUP(F28/$D$5,0))) -> 0 | H28: =IF(AND(F28<$D$5,F28>0),"can be merged","") | K28: Total | N28: =SUM(N20:N27) -> 0 | O28: =SUM(O20:O27) -> 0
B29: Migration Rate: | C29: 12-2 | E29: 12-2 | F29: =ROUNDUP((D28*$B$28)*$B$30,0) -> 0 | G29: =IF($D$5=0,0,IF(AND(F29>0,F29-$D$5<6),ROUNDUP((F29-5)/$D$5,0),ROUNDUP(F29/$D$5,0))) -> 0 | H29: =IF(AND(F29<$D$5,F29>0),"can be merged","") | J29: BS in Information System (BSIS) | K29: 1-1 | M29: 1-1 | O29: =IF($L$5=0,0,IF(AND(N29>0,N29-$L$5<6),ROUNDUP((N29-5)/$L$5,0),ROUNDUP(N29/$L$5,0))) -> 0 | P29: =IF(AND(N29<$L$5,N29>0),"can be merged","")
C30: Total | F30: =SUM(F26:F29) -> 0 | G30: =SUM(G26:G29) -> 0 | K30: 1-2 | M30: 1-2 | N30: =ROUNDUP((L29*$J$33)*$J$35,0) -> 0 | O30: =IF($L$5=0,0,IF(AND(N30>0,N30-$L$5<6),ROUNDUP((N30-5)/$L$5,0),ROUNDUP(N30/$L$5,0))) -> 0 | P30: =IF(AND(N30<$L$5,N30>0),"can be merged","")
B31: HUMSS | C31: 11-1 | E31: 11-1 | G31: =IF($D$5=0,0,IF(AND(F31>0,F31-$D$5<6),ROUNDUP((F31-5)/$D$5,0),ROUNDUP(F31/$D$5,0))) -> 0 | H31: =IF(AND(F31<$D$5,F31>0),"can be merged","") | K31: 2-1 | M31: 2-1 | N31: =ROUNDUP((L30*$J$33)*$J$35,0) -> 0 | O31: =IF($L$5=0,0,IF(AND(N31>0,N31-$L$5<6),ROUNDUP((N31-5)/$L$5,0),ROUNDUP(N31/$L$5,0))) -> 0 | P31: =IF(AND(N31<$L$5,N31>0),"can be merged","")
B32: Retention Rate: | C32: 11-2 | E32: 11-2 | F32: =ROUNDUP((D31*$B$33)*$B$35,0) -> 0 | G32: =IF($D$5=0,0,IF(AND(F32>0,F32-$D$5<6),ROUNDUP((F32-5)/$D$5,0),ROUNDUP(F32/$D$5,0))) -> 0 | H32: =IF(AND(F32<$D$5,F32>0),"can be merged","") | J32: Retention Rate: | K32: 2-2 | M32: 2-2 | N32: =ROUNDUP((L31*$J$33)*$J$35,0) -> 0 | O32: =IF($L$5=0,0,IF(AND(N32>0,N32-$L$5<6),ROUNDUP((N32-5)/$L$5,0),ROUNDUP(N32/$L$5,0))) -> 0 | P32: =IF(AND(N32<$L$5,N32>0),"can be merged","")
C33: 12-1 | E33: 12-1 | F33: =ROUNDUP((D32*$B$33)*$B$35,0) -> 0 | G33: =IF($D$5=0,0,IF(AND(F33>0,F33-$D$5<6),ROUNDUP((F33-5)/$D$5,0),ROUNDUP(F33/$D$5,0))) -> 0 | H33: =IF(AND(F33<$D$5,F33>0),"can be merged","") | K33: 3-1 | M33: 3-1 | N33: =ROUNDUP((L32*$J$33)*$J$35,0) -> 0 | O33: =IF($L$5=0,0,IF(AND(N33>0,N33-$L$5<6),ROUNDUP((N33-5)/$L$5,0),ROUNDUP(N33/$L$5,0))) -> 0 | P33: =IF(AND(N33<$L$5,N33>0),"can be merged","")
B34: Migration Rate: | C34: 12-2 | E34: 12-2 | F34: =ROUNDUP((D33*$B$33)*$B$35,0) -> 0 | G34: =IF($D$5=0,0,IF(AND(F34>0,F34-$D$5<6),ROUNDUP((F34-5)/$D$5,0),ROUNDUP(F34/$D$5,0))) -> 0 | H34: =IF(AND(F34<$D$5,F34>0),"can be merged","") | J34: Migration Rate: | K34: 3-2 | M34: 3-2 | N34: =ROUNDUP((L33*$J$33)*$J$35,0) -> 0 | O34: =IF($L$5=0,0,IF(AND(N34>0,N34-$L$5<6),ROUNDUP((N34-5)/$L$5,0),ROUNDUP(N34/$L$5,0))) -> 0 | P34: =IF(AND(N34<$L$5,N34>0),"can be merged","")
C35: Total | F35: =SUM(F31:F34) -> 0 | G35: =SUM(G31:G34) -> 0 | K35: 4-1 | M35: 4-1 | N35: =ROUNDUP((L34*$J$33)*$J$35,0) -> 0 | O35: =IF($L$5=0,0,IF(AND(N35>0,N35-$L$5<6),ROUNDUP((N35-5)/$L$5,0),ROUNDUP(N35/$L$5,0))) -> 0 | P35: =IF(AND(N35<$L$5,N35>0),"can be merged","")
B36: IT-MAWD | C36: 11-1 | E36: 11-1 | G36: =IF($D$5=0,0,IF(AND(F36>0,F36-$D$5<6),ROUNDUP((F36-5)/$D$5,0),ROUNDUP(F36/$D$5,0))) -> 0 | H36: =IF(AND(F36<$D$5,F36>0),"can be merged","") | K36: 4-2 | M36: 4-2 | N36: =ROUNDUP((L35*$J$33)*$J$35,0) -> 0 | O36: =IF($L$5=0,0,IF(AND(N36>0,N36-$L$5<6),ROUNDUP((N36-5)/$L$5,0),ROUNDUP(N36/$L$5,0))) -> 0 | P36: =IF(AND(N36<$L$5,N36>0),"can be merged","")
B37: Retention Rate: | C37: 11-2 | E37: 11-2 | F37: =ROUNDUP((D36*$B$38)*$B$40,0) -> 0 | G37: =IF($D$5=0,0,IF(AND(F37>0,F37-$D$5<6),ROUNDUP((F37-5)/$D$5,0),ROUNDUP(F37/$D$5,0))) -> 0 | H37: =IF(AND(F37<$D$5,F37>0),"can be merged","") | K37: Total | N37: =SUM(N29:N36) -> 0 | O37: =SUM(O29:O36) -> 0
C38: 12-1 | E38: 12-1 | F38: =ROUNDUP((D37*$B$38)*$B$40,0) -> 0 | G38: =IF($D$5=0,0,IF(AND(F38>0,F38-$D$5<6),ROUNDUP((F38-5)/$D$5,0),ROUNDUP(F38/$D$5,0))) -> 0 | H38: =IF(AND(F38<$D$5,F38>0),"can be merged","") | J38: BS in Computer Engineering (BSCPE) | K38: 1-1 | M38: 1-1 | O38: =IF($L$5=0,0,IF(AND(N38>0,N38-$L$5<6),ROUNDUP((N38-5)/$L$5,0),ROUNDUP(N38/$L$5,0))) -> 0 | P38: =IF(AND(N38<$L$5,N38>0),"can be merged","")
B39: Migration Rate: | C39: 12-2 | E39: 12-2 | F39: =ROUNDUP((D38*$B$38)*$B$40,0) -> 0 | G39: =IF($D$5=0,0,IF(AND(F39>0,F39-$D$5<6),ROUNDUP((F39-5)/$D$5,0),ROUNDUP(F39/$D$5,0))) -> 0 | H39: =IF(AND(F39<$D$5,F39>0),"can be merged","") | K39: 1-2 | M39: 1-2 | N39: =ROUNDUP((L38*$J$42)*$J$44,0) -> 0 | O39: =IF($L$5=0,0,IF(AND(N39>0,N39-$L$5<6),ROUNDUP((N39-5)/$L$5,0),ROUNDUP(N39/$L$5,0))) -> 0 | P39: =IF(AND(N39<$L$5,N39>0),"can be merged","")
C40: Total | F40: =SUM(F36:F39) -> 0 | G40: =SUM(G36:G39) -> 0 | K40: 2-1 | M40: 2-1 | N40: =ROUNDUP((L39*$J$42)*$J$44,0) -> 0 | O40: =IF($L$5=0,0,IF(AND(N40>0,N40-$L$5<6),ROUNDUP((N40-5)/$L$5,0),ROUNDUP(N40/$L$5,0))) -> 0 | P40: =IF(AND(N40<$L$5,N40>0),"can be merged","")
B41: IT-DA | C41: 11-1 | E41: 11-1 | G41: =IF($D$5=0,0,IF(AND(F41>0,F41-$D$5<6),ROUNDUP((F41-5)/$D$5,0),ROUNDUP(F41/$D$5,0))) -> 0 | H41: =IF(AND(F41<$D$5,F41>0),"can be merged","") | J41: Retention Rate: | K41: 2-2 | M41: 2-2 | N41: =ROUNDUP((L40*$J$42)*$J$44,0) -> 0 | O41: =IF($L$5=0,0,IF(AND(N41>0,N41-$L$5<6),ROUNDUP((N41-5)/$L$5,0),ROUNDUP(N41/$L$5,0))) -> 0 | P41: =IF(AND(N41<$L$5,N41>0),"can be merged","")
B42: Retention Rate: | C42: 11-2 | E42: 11-2 | F42: =ROUNDUP((D41*$B$43)*$B$45,0) -> 0 | G42: =IF($D$5=0,0,IF(AND(F42>0,F42-$D$5<6),ROUNDUP((F42-5)/$D$5,0),ROUNDUP(F42/$D$5,0))) -> 0 | H42: =IF(AND(F42<$D$5,F42>0),"can be merged","") | K42: 3-1 | M42: 3-1 | N42: =ROUNDUP((L41*$J$42)*$J$44,0) -> 0 | O42: =IF($L$5=0,0,IF(AND(N42>0,N42-$L$5<6),ROUNDUP((N42-5)/$L$5,0),ROUNDUP(N42/$L$5,0))) -> 0 | P42: =IF(AND(N42<$L$5,N42>0),"can be merged","")
...

Sheet 3.1 - Tertiary - Term 1
A1: Program | B1: Year - Term | C1: Course Code | D1: Course Title | E1: Field of Specialization | F1: LEC | G1: LAB | H1: TOTAL | I1: Section Count | J1: Teaching Load
A2: BSIT-24-01
A3: BSIT | B3: 1-1 | C3: CITE1004 | D3: Introduction to Computing | E3: Information Technology | F3: 2 | G3: 1.5 | H3: =SUM(F3:G3) -> 3.5 | I3: 6 | J3: =I3*H3 -> 21 | K3: =IF(I3>0,F3,"") -> 2
A4: BSIT | B4: 1-1 | C4: CITE1003 | D4: Computer Programming 1 | E4: Information Technology | F4: 2 | G4: 1.5 | H4: =SUM(F4:G4) -> 3.5 | I4: 6 | J4: =I4*H4 -> 21 | K4: =IF(I4>0,F4,"") -> 2
A5: BSIT | B5: 1-1 | C5: GEDC1002 | D5: The Contemporary World | F5: 3 | H5: =SUM(F5:G5) -> 3 | I5: 6 | J5: =I5*H5 -> 18 | K5: =IF(I5>0,F5,"") -> 3
A6: BSIT | B6: 1-1 | C6: STIC1002 | D6: Euthenics 1 | F6: 1 | H6: =SUM(F6:G6) -> 1 | I6: 6 | J6: =I6*H6 -> 6 | K6: =IF(I6>0,F6,"") -> 1
A7: BSIT | B7: 1-1 | C7: GEDC1016 | D7: Purposive Communication | E7: English/Foreign Language | F7: 3 | H7: =SUM(F7:G7) -> 3 | I7: 6 | J7: =I7*H7 -> 18 | K7: =IF(I7>0,F7,"") -> 3
A8: BSIT | B8: 1-1 | C8: NSTP1008 | D8: National Service Training Program 1 | F8: 3 | H8: =SUM(F8:G8) -> 3 | I8: 6 | J8: =I8*H8 -> 18 | K8: =IF(I8>0,F8,"") -> 3
A9: BSIT | B9: 1-1 | C9: PHED1005 | D9: P.E./PATHFIT 1: Movement Competency Training | E9: Physical Education | F9: 2 | H9: =SUM(F9:G9) -> 2 | I9: 6 | J9: =I9*H9 -> 12 | K9: =IF(I9>0,F9,"") -> 2
A10: BSIT | B10: 1-1 | C10: GEDC1041 | D10: Philippine Popular Culture | F10: 3 | H10: =SUM(F10:G10) -> 3 | I10: 6 | J10: =I10*H10 -> 18 | K10: =IF(I10>0,F10,"") -> 3
A11: BSIT | B11: 1-1 | C11: GEDC1008 | D11: Understanding the Self | F11: 3 | H11: =SUM(F11:G11) -> 3 | I11: 6 | J11: =I11*H11 -> 18 | K11: =IF(I11>0,F11,"") -> 3
K12: =IF(I12>0,F12,"")
A13: BSIT-22-01 | K13: =IF(I13>0,F13,"")
A14: BSIT | B14: 2-1 | C14: COSC1003 | D14: Data Structures and Algorithms | E14: Information Technology | F14: 2 | G14: 1.5 | H14: =SUM(F14:G14) -> 3.5 | I14: 5 | J14: =I14*H14 -> 17.5 | K14: =IF(I14>0,F14,"") -> 2
A15: BSIT | B15: 2-1 | C15: GEDC1006 | D15: Readings in Philippine History | E15: Social and Behavioral Science | F15: 3 | H15: =SUM(F15:G15) -> 3 | I15: 5 | J15: =I15*H15 -> 15 | K15: =IF(I15>0,F15,"") -> 3
A16: BSIT | B16: 2-1 | C16: PHED1007 | D16: P.E./PATHFIT 3: Individual-Dual Sports | E16: Physical Education | F16: 2 | H16: =SUM(F16:G16) -> 2 | I16: 5 | J16: =I16*H16 -> 10 | K16: =IF(I16>0,F16,"") -> 2
A17: BSIT | B17: 2-1 | C17: GEDC1014 | D17: Rizal's Life and Works | E17: Social and Behavioral Science | F17: 3 | H17: =SUM(F17:G17) -> 3 | I17: 5 | J17: =I17*H17 -> 15 | K17: =IF(I17>0,F17,"") -> 3
A18: BSIT | B18: 2-1 | C18: COSC1007 | D18: Human-Computer Interaction | E18: Information Technology | F18: 2 | G18: 1.5 | H18: =SUM(F18:G18) -> 3.5 | I18: 5 | J18: =I18*H18 -> 17.5 | K18: =IF(I18>0,F18,"") -> 2
A19: BSIT | B19: 2-1 | D19: IT Elective 1 | F19: 2 | G19: 1.5 | H19: =SUM(F19:G19) -> 3.5 | I19: 5 | J19: =I19*H19 -> 17.5 | K19: =IF(I19>0,F19,"") -> 2
A20: BSIT | B20: 2-1 | C20: COSC1001 | D20: Principles of Communication | E20: Information Technology | F20: 3 | H20: =SUM(F20:G20) -> 3 | I20: 5 | J20: =I20*H20 -> 15 | K20: =IF(I20>0,F20,"") -> 3
A21: BSIT | B21: 2-1 | C21: COSC1008 | D21: Platform Technology (Operating Systems) | E21: Information Technology | F21: 2 | G21: 1.5 | H21: =SUM(F21:G21) -> 3.5 | I21: 5 | J21: =I21*H21 -> 17.5 | K21: =IF(I21>0,F21,"") -> 2
K22: =IF(I22>0,F22,"")
A23: BSIT-22-01 | K23: =IF(I23>0,F23,"")
A24: BSIT | B24: 3-1 | C24: CITE1008 | D24: Application Development and Emerging Technologies | E24: Information Technology | F24: 2 | G24: 1.5 | H24: =SUM(F24:G24) -> 3.5 | I24: 4 | J24: =I24*H24 -> 14 | K24: =IF(I24>0,F24,"") -> 2
A25: BSIT | B25: 3-1 | C25: INSY1011 | D25: Advanced Database Systems | E25: Information Technology | F25: 2 | G25: 1.5 | H25: =SUM(F25:G25) -> 3.5 | I25: 4 | J25: =I25*H25 -> 14 | K25: =IF(I25>0,F25,"") -> 2
A26: BSIT | B26: 3-1 | C26: INSY1024 | D26: Event-Driven Programming | E26: Information Technology | F26: 2 | G26: 1.5 | H26: =SUM(F26:G26) -> 3.5 | I26: 4 | J26: =I26*H26 -> 14 | K26: =IF(I26>0,F26,"") -> 2
A27: BSIT | B27: 3-1 | C27: INTE1025 | D27: Data and Digital Communications (Data Communications) | E27: Information Technology | F27: 3 | H27: =SUM(F27:G27) -> 3 | I27: 4 | J27: =I27*H27 -> 12 | K27: =IF(I27>0,F27,"") -> 3
A28: BSIT | B28: 3-1 | C28: INSY1003 | D28: Professional Issues in Information Systems and Technology | E28: Information Technology | F28: 3 | H28: =SUM(F28:G28) -> 3 | I28: 4 | J28: =I28*H28 -> 12 | K28: =IF(I28>0,F28,"") -> 3
A29: BSIT | B29: 3-1 | D29: IT Elective 2 | E29: Information Technology | F29: 2 | G29: 1.5 | H29: =SUM(F29:G29) -> 3.5 | I29: 4 | J29: =I29*H29 -> 14 | K29: =IF(I29>0,F29,"") -> 2
A30: BSIT | B30: 3-1 | C30: INTE1056 | D30: Advanced Systems Integration and Architecture | E30: Information Technology | F30: 2 | G30: 1.5 | H30: =SUM(F30:G30) -> 3.5 | I30: 4 | J30: =I30*H30 -> 14 | K30: =IF(I30>0,F30,"") -> 2
K31: =IF(I31>0,F31,"")
A32: BSIT-20-01 | K32: =IF(I32>0,F32,"")
A33: BSIT | B33: 4-1 | C33: STIC1007 | D33: Euthenics 2 | F33: 1 | H33: =SUM(F33:G33) -> 1 | I33: 3 | J33: =I33*H33 -> 3 | K33: =IF(I33>0,F33,"") -> 1
A34: BSIT | B34: 4-1 | C34: INTE1039 | D34: IT Capstone Project 2 | E34: Information Technology | F34: 2 | H34: =SUM(F34:G34) -> 2 | I34: 3 | J34: =I34*H34 -> 6 | K34: =IF(I34>0,F34,"") -> 2
A35: BSIT | B35: 4-1 | D35: IT Elective 4 | E35: Information Technology | F35: 2 | G35: 1.5 | H35: =SUM(F35:G35) -> 3.5 | I35: 3 | J35: =I35*H35 -> 10.5 | K35: =IF(I35>0,F35,"") -> 2
A36: BSIT | B36: 4-1 | C36: INTE1041 | D36: Computer Graphics Programming | E36: Information Technology | F36: 2 | G36: 1.5 | H36: =SUM(F36:G36) -> 3.5 | I36: 3 | J36: =I36*H36 -> 10.5 | K36: =IF(I36>0,F36,"") -> 2
A37: BSIT | B37: 4-1 | C37: INTE1013 | D37: IT Service Management | E37: Information Technology | F37: 3 | H37: =SUM(F37:G37) -> 3 | I37: 3 | J37: =I37*H37 -> 9 | K37: =IF(I37>0,F37,"") -> 3
A38: BSIT | B38: 4-1 | C38: INSY1005 | D38: Information Assurance and Security (Data Privacy) | E38: Information Technology | F38: 2 | G38: 1.5 | H38: =SUM(F38:G38) -> 3.5 | I38: 3 | J38: =I38*H38 -> 10.5 | K38: =IF(I38>0,F38,"") -> 2
A39: BSIT | B39: 4-1 | C39: INTE1030 | D39: Network Technology 2 | E39: Information Technology | F39: 2 | G39: 1.5 | H39: =SUM(F39:G39) -> 3.5 | I39: 3 | J39: =I39*H39 -> 10.5 | K39: =IF(I39>0,F39,"") -> 2
K40: =IF(I40>0,F40,"")
...

Sheet 3.2 - Tertiary - Term 2
A1: Program | B1: Year - Term | C1: Course Code | D1: Course Title | E1: Field of Specialization | F1: LEC | G1: LAB | H1: TOTAL | I1: Section Count | J1: Teaching Load
A2: BSIT-24-01
A3: BSIT | B3: 1-2 | C3: CITE1006 | D3: Computer Programming 2 | E3: Information Technology | F3: 2 | G3: 1.5 | H3: =SUM(F3:G3) -> 3.5 | I3: ='2 - Section Count Projection'!$O$12 -> 0 | J3: =I3*H3 -> 0 | K3: =IF(I3>0,F3,"")
A4: BSIT | B4: 1-2 | C4: COSC1002 | D4: Discrete Structures 1 (Discrete Mathematics) | E4: Information Technology | F4: 3 | H4: =SUM(F4:G4) -> 3 | I4: ='2 - Section Count Projection'!$O$12 -> 0 | J4: =I4*H4 -> 0 | K4: =IF(I4>0,F4,"")
A5: BSIT | B5: 1-2 | C5: GEDC1010 | D5: Art Appreciation | E5: Social and Behavioral Science | F5: 3 | H5: =SUM(F5:G5) -> 3 | I5: ='2 - Section Count Projection'!$O$12 -> 0 | J5: =I5*H5 -> 0 | K5: =IF(I5>0,F5,"")
A6: BSIT | B6: 1-2 | C6: NSTP1010 | D6: National Service Training Program 2 | F6: 3 | H6: =SUM(F6:G6) -> 3 | I6: ='2 - Section Count Projection'!$O$12 -> 0 | J6: =I6*H6 -> 0 | K6: =IF(I6>0,F6,"")
A7: BSIT | B7: 1-2 | C7: PHED1006 | D7: PE/PATHFIT 2: Exercise-based Fitness Activities | E7: Physical Education | F7: 2 | H7: =SUM(F7:G7) -> 2 | I7: ='2 - Section Count Projection'!$O$12 -> 0 | J7: =I7*H7 -> 0 | K7: =IF(I7>0,F7,"")
A8: BSIT | B8: 1-2 | C8: GEDC1005 | D8: Mathematics in the Modern World | E8: Mathematics | F8: 3 | H8: =SUM(F8:G8) -> 3 | I8: ='2 - Section Count Projection'!$O$12 -> 0 | J8: =I8*H8 -> 0 | K8: =IF(I8>0,F8,"")
A9: BSIT | B9: 1-2 | C9: GEDC1013 | D9: Science, Technology, and Society | F9: 3 | H9: =SUM(F9:G9) -> 3 | I9: ='2 - Section Count Projection'!$O$12 -> 0 | J9: =I9*H9 -> 0 | K9: =IF(I9>0,F9,"")
A10: BSIT | B10: 1-2 | C10: GEDC1009 | D10: Ethics | E10: Social and Behavioral Science | F10: 3 | H10: =SUM(F10:G10) -> 3 | I10: ='2 - Section Count Projection'!$O$12 -> 0 | J10: =I10*H10 -> 0 | K10: =IF(I10>0,F10,"")
A11: BSIT | B11: 1-2 | C11: INTE1006 | D11: Systems Administration and Maintenance | E11: Information Technology | F11: 2 | G11: 1.5 | H11: =SUM(F11:G11) -> 3.5 | I11: ='2 - Section Count Projection'!$O$12 -> 0 | J11: =I11*H11 -> 0 | K11: =IF(I11>0,F11,"")
K12: =IF(I12>0,F12,"")
A13: BSIT-22-01 | K13: =IF(I13>0,F13,"")
A14: BSIT | B14: 2-2 | C14: CITE1011 | D14: Information Management | E14: Information Technology | F14: 2 | G14: 1.5 | H14: =SUM(F14:G14) -> 3.5 | I14: ='2 - Section Count Projection'!$O$14 -> 0 | J14: =I14*H14 -> 0 | K14: =IF(I14>0,F14,"")
A15: BSIT | B15: 2-2 | C15: GEDC1041 | D15: Philippine Popular Culture | F15: 3 | H15: =SUM(F15:G15) -> 3 | I15: ='2 - Section Count Projection'!$O$14 -> 0 | J15: =I15*H15 -> 0 | K15: =IF(I15>0,F15,"")
A16: BSIT | B16: 2-2 | C16: PHED1008 | D16: P.E./PATHFIT 4: Team Sports | E16: Physical Education | F16: 2 | H16: =SUM(F16:G16) -> 2 | I16: ='2 - Section Count Projection'!$O$14 -> 0 | J16: =I16*H16 -> 0 | K16: =IF(I16>0,F16,"")
A17: BSIT | B17: 2-2 | C17: INTE1005 | D17: Network Technology 1 | E17: Information Technology | F17: 2 | G17: 1.5 | H17: =SUM(F17:G17) -> 3.5 | I17: ='2 - Section Count Projection'!$O$14 -> 0 | J17: =I17*H17 -> 0 | K17: =IF(I17>0,F17,"")
A18: BSIT | B18: 2-2 | C18: INTE1020 | D18: Quantitative Methods | E18: Mathematics | F18: 3 | H18: =SUM(F18:G18) -> 3 | I18: ='2 - Section Count Projection'!$O$14 -> 0 | J18: =I18*H18 -> 0 | K18: =IF(I18>0,F18,"")
A19: BSIT | B19: 2-2 | C19: BUSS1013 | D19: Technopreneurship | E19: Business and Management | F19: 3 | H19: =SUM(F19:G19) -> 3 | I19: ='2 - Section Count Projection'!$O$14 -> 0 | J19: =I19*H19 -> 0 | K19: =IF(I19>0,F19,"")
A20: BSIT | B20: 2-2 | C20: INTE1021 | D20: Systems Integration and Architecture | E20: Information Technology | F20: 2 | G20: 1.5 | H20: =SUM(F20:G20) -> 3.5 | I20: ='2 - Section Count Projection'!$O$14 -> 0 | J20: =I20*H20 -> 0 | K20: =IF(I20>0,F20,"")
A21: BSIT | B21: 2-2 | C21: INTE1010 | D21: Integrative Programming | E21: Information Technology | F21: 2 | G21: 1.5 | H21: =SUM(F21:G21) -> 3.5 | I21: ='2 - Section Count Projection'!$O$14 -> 0 | J21: =I21*H21 -> 0 | K21: =IF(I21>0,F21,"")
K22: =IF(I22>0,F22,"")
A23: BSIT-22-01 | K23: =IF(I23>0,F23,"")
A24: BSIT | B24: 3-2 | C24: INTE1083 | D24: Web Systems and Technologies | E24: Information Technology | F24: 2 | G24: 1.5 | H24: =SUM(F24:G24) -> 3.5 | I24: ='2 - Section Count Projection'!$O$16 -> 0 | J24: =I24*H24 -> 0 | K24: =IF(I24>0,F24,"")
A25: BSIT | B25: 3-2 | C25: INSY1007 | D25: Management Information Systems | E25: Information Technology | F25: 3 | H25: =SUM(F25:G25) -> 3 | I25: ='2 - Section Count Projection'!$O$16 -> 0 | J25: =I25*H25 -> 0 | K25: =IF(I25>0,F25,"")
A26: BSIT | B26: 3-2 | C26: INTE1031 | D26: IT Capstone Project 1 | E26: Information Technology | F26: 2 | H26: 2 | I26: ='2 - Section Count Projection'!$O$16 -> 0 | J26: =I26*H26 -> 0 | K26: =IF(I26>0,F26,"")
A27: BSIT | B27: 3-2 | C27: GEDC1045 | D27: Great Books | E27: English/Foreign Language | F27: 3 | H27: =SUM(F27:G27) -> 3 | I27: ='2 - Section Count Projection'!$O$16 -> 0 | J27: =I27*H27 -> 0 | K27: =IF(I27>0,F27,"")
A28: BSIT | B28: 3-2 | D28: IT Elective 3 | E28: Information Technology | F28: 2 | G28: 1.5 | H28: =SUM(F28:G28) -> 3.5 | I28: ='2 - Section Count Projection'!$O$16 -> 0 | J28: =I28*H28 -> 0 | K28: =IF(I28>0,F28,"")
A29: BSIT | B29: 3-2 | C29: INTE1084 | D29: Mobile Systems and Technologies | E29: Information Technology | F29: 2 | G29: 1.5 | H29: =SUM(F29:G29) -> 3.5 | I29: ='2 - Section Count Projection'!$O$16 -> 0 | J29: =I29*H29 -> 0 | K29: =IF(I29>0,F29,"")
A30: BSIT | B30: 3-2 | C30: INSY1010 | D30: Information Assurance and Security (Cybersecurity Fundamentals ) | E30: Information Technology | F30: 2 | G30: 1.5 | H30: =SUM(F30:G30) -> 3.5 | I30: ='2 - Section Count Projection'!$O$16 -> 0 | J30: =I30*H30 -> 0 | K30: =IF(I30>0,F30,"")
K31: =IF(I31>0,F31,"")
A32: BSIT-20-01 | K32: =IF(I32>0,F32,"")
A33: BSIT | B33: 4-2 | C33: INTE1043 | D33: IT Practicum (486 hours) | E33: Information Technology | F33: 0 | G33: 3 | H33: 3 | I33: ='2 - Section Count Projection'!$O$18 -> 0 | J33: =I33*H33 -> 0 | K33: =IF(I33>0,F33,"")
K34: =IF(I34>0,F34,"")
A35: BSCS-24-01 | K35: =IF(I35>0,F35,"")
A36: BSCS | B36: 1-2 | C36: CITE1006 | D36: Computer Programming 2 | E36: Information Technology | F36: 2 | G36: 1.5 | H36: =SUM(F36:G36) -> 3.5 | I36: ='2 - Section Count Projection'!$O$21 -> 0 | J36: =I36*H36 -> 0 | K36: =IF(I36>0,F36,"")
A37: BSCS | B37: 1-2 | C37: COSC1002 | D37: Discrete Structures 1 (Discrete Mathematics) | E37: Information Technology | F37: 3 | H37: =SUM(F37:G37) -> 3 | I37: ='2 - Section Count Projection'!$O$21 -> 0 | J37: =I37*H37 -> 0 | K37: =IF(I37>0,F37,"")
A38: BSCS | B38: 1-2 | C38: GEDC1010 | D38: Art Appreciation | E38: Social and Behavioral Science | F38: 3 | H38: =SUM(F38:G38) -> 3 | I38: ='2 - Section Count Projection'!$O$21 -> 0 | J38: =I38*H38 -> 0 | K38: =IF(I38>0,F38,"")
A39: BSCS | B39: 1-2 | C39: NSTP1010 | D39: National Service Training Program 2 | F39: 3 | H39: =SUM(F39:G39) -> 3 | I39: ='2 - Section Count Projection'!$O$21 -> 0 | J39: =I39*H39 -> 0 | K39: =IF(I39>0,F39,"")
A40: BSCS | B40: 1-2 | C40: PHED1006 | D40: P.E./PATHFIT 2: Exercise-based Fitness Activities | E40: Physical Education | F40: 2 | H40: =SUM(F40:G40) -> 2 | I40: ='2 - Section Count Projection'!$O$21 -> 0 | J40: =I40*H40 -> 0 | K40: =IF(I40>0,F40,"")
...

Sheet 3.3 - SHS Term 1 
A2: Strand/Track | B2: Grade Level Term | C2: Subject Classification | D2: Subject Title | E2: Field of Specialization | F2: LEC | G2: TOTAL | H2: Section Count | I2: Teaching Load
A3: ABM | B3: 11-1 | C3: Core | D3: Oral Communication | E3: English | F3: 3 | G3: =SUM(F3:F3) -> 3 | H3: 3 | I3: =H3*G3 -> 9 | K3: =IF(I3>0,F3,"") -> 3
A4: ABM | B4: 11-1 | C4: Core | D4: General Mathematics | E4: Mathematics | F4: 3 | G4: =SUM(F4:F4) -> 3 | H4: 3 | I4: =H4*G4 -> 9 | K4: =IF(I4>0,F4,"") -> 3
A5: ABM | B5: 11-1 | C5: Core | D5: 21st Century Literature from the Philippines and the World | E5: English | F5: 3 | G5: =SUM(F5:F5) -> 3 | H5: 3 | I5: =H5*G5 -> 9 | K5: =IF(I5>0,F5,"") -> 3
A6: ABM | B6: 11-1 | C6: Core | D6: Media and Information Literacy | F6: 3 | G6: =SUM(F6:F6) -> 3 | H6: 3 | I6: =H6*G6 -> 9 | K6: =IF(I6>0,F6,"") -> 3
A7: ABM | B7: 11-1 | C7: Core | D7: Introduction to the Philosophy of the Human Person | E7: Social and Behavioral Sciences | F7: 3 | G7: =SUM(F7:F7) -> 3 | H7: 3 | I7: =H7*G7 -> 9 | K7: =IF(I7>0,F7,"") -> 3
A8: ABM | B8: 11-1 | C8: Core | D8: Physical Education and Health 1 | E8: Physical Education | F8: 3 | G8: =SUM(F8:F8) -> 3 | H8: 3 | I8: =H8*G8 -> 9 | K8: =IF(I8>0,F8,"") -> 3
A9: ABM | B9: 11-1 | C9: Specialized | D9: Business Mathematics | E9: Business and Management | F9: 3 | G9: =SUM(F9:F9) -> 3 | H9: 3 | I9: =H9*G9 -> 9 | K9: =IF(I9>0,F9,"") -> 3
A10: ABM | B10: 11-1 | C10: Specialized | D10: Organization and Management | E10: Business and Management | F10: 3 | G10: =SUM(F10:F10) -> 3 | H10: 3 | I10: =H10*G10 -> 9 | K10: =IF(I10>0,F10,"") -> 3
A11: ABM | B11: 11-1 | D11: Homeroom | F11: 1 | G11: =SUM(F11:F11) -> 1 | H11: 3 | I11: =H11*G11 -> 3 | K11: =IF(I11>0,F11,"") -> 1
A12: ABM | B12: 11-1 | D12: Student Club and Org | F12: 1 | G12: =SUM(F12:F12) -> 1 | H12: 3 | I12: =H12*G12 -> 3 | K12: =IF(I12>0,F12,"") -> 1
K13: =IF(I13>0,F13,"")
A14: ABM | B14: 12-1 | C14: Core | D14: Personal Development | E14: Social and Behavioral Sciences | F14: 3 | G14: =SUM(F14:F14) -> 3 | H14: 3 | I14: =H14*G14 -> 9 | K14: =IF(I14>0,F14,"") -> 3
A15: ABM | B15: 12-1 | C15: Core | D15: Pagbasa at Pagsusuri ng Iba't Ibang Teksto Tungo sa Pananaliksik | E15: Filipino | F15: 3 | G15: =SUM(F15:F15) -> 3 | H15: 3 | I15: =H15*G15 -> 9 | K15: =IF(I15>0,F15,"") -> 3
A16: ABM | B16: 12-1 | C16: Core | D16: Physical Science | E16: Sciences | F16: 3 | G16: =SUM(F16:F16) -> 3 | H16: 3 | I16: =H16*G16 -> 9 | K16: =IF(I16>0,F16,"") -> 3
A17: ABM | B17: 12-1 | C17: Core | D17: Physical Education and Health 3 | E17: Physical Education | F17: 3 | G17: =SUM(F17:F17) -> 3 | H17: 3 | I17: =H17*G17 -> 9 | K17: =IF(I17>0,F17,"") -> 3
A18: ABM | B18: 12-1 | C18: Applied | D18: Practical Research 2 | F18: 3 | G18: =SUM(F18:F18) -> 3 | H18: 3 | I18: =H18*G18 -> 9 | K18: =IF(I18>0,F18,"") -> 3
A19: ABM | B19: 12-1 | C19: Applied | D19: Filipino sa Piling Larangan | E19: Filipino | F19: 3 | G19: =SUM(F19:F19) -> 3 | H19: 3 | I19: =H19*G19 -> 9 | K19: =IF(I19>0,F19,"") -> 3
A20: ABM | B20: 12-1 | C20: Applied | D20: English for Academic and Professional Purposes | E20: English | F20: 3 | G20: =SUM(F20:F20) -> 3 | H20: 3 | I20: =H20*G20 -> 9 | K20: =IF(I20>0,F20,"") -> 3
A21: ABM | B21: 12-1 | C21: Specialized | D21: Business Finance | E21: Business and Management | F21: 3 | G21: =SUM(F21:F21) -> 3 | H21: 3 | I21: =H21*G21 -> 9 | K21: =IF(I21>0,F21,"") -> 3
A22: ABM | B22: 12-1 | C22: Specialized | D22: Fundamentals of Accountancy, Business and Management 2 | E22: Business and Management | F22: 3 | G22: =SUM(F22:F22) -> 3 | H22: 3 | I22: =H22*G22 -> 9 | K22: =IF(I22>0,F22,"") -> 3
A23: ABM | B23: 12-1 | D23: Homeroom | F23: 1 | G23: =SUM(F23:F23) -> 1 | H23: 3 | I23: =H23*G23 -> 3 | K23: =IF(I23>0,F23,"") -> 1
A24: ABM | B24: 12-1 | D24: Student Club and Org | F24: 1 | G24: =SUM(F24:F24) -> 1 | H24: 3 | I24: =H24*G24 -> 3 | K24: =IF(I24>0,F24,"") -> 1
K25: =IF(I25>0,F25,"")
A26: STEM | B26: 11-1 | C26: Core | D26: Oral Communication | E26: English | F26: 3 | G26: =SUM(F26:F26) -> 3 | H26: 9 | I26: =H26*G26 -> 27 | K26: =IF(I26>0,F26,"") -> 3
A27: STEM | B27: 11-1 | C27: Core | D27: General Mathematics | E27: Mathematics | F27: 3 | G27: =SUM(F27:F27) -> 3 | H27: 9 | I27: =H27*G27 -> 27 | K27: =IF(I27>0,F27,"") -> 3
A28: STEM | B28: 11-1 | C28: Core | D28: 21st Century Literature from the Philippines and the World | E28: Social and Behavioral Sciences | F28: 3 | G28: =SUM(F28:F28) -> 3 | H28: 9 | I28: =H28*G28 -> 27 | K28: =IF(I28>0,F28,"") -> 3
A29: STEM | B29: 11-1 | C29: Core | D29: Media and Information Literacy | F29: 3 | G29: =SUM(F29:F29) -> 3 | H29: 9 | I29: =H29*G29 -> 27 | K29: =IF(I29>0,F29,"") -> 3
A30: STEM | B30: 11-1 | C30: Core | D30: Introduction to the Philosophy of the Human Person | E30: Social and Behavioral Sciences | F30: 3 | G30: =SUM(F30:F30) -> 3 | H30: 9 | I30: =H30*G30 -> 27 | K30: =IF(I30>0,F30,"") -> 3
A31: STEM | B31: 11-1 | C31: Core | D31: Physical Education and Health 1 | E31: Physical Education | F31: 3 | G31: =SUM(F31:F31) -> 3 | H31: 9 | I31: =H31*G31 -> 27 | K31: =IF(I31>0,F31,"") -> 3
A32: STEM | B32: 11-1 | C32: Specialized | D32: Pre-Calculus | E32: Mathematics | F32: 3 | G32: =SUM(F32:F32) -> 3 | H32: 9 | I32: =H32*G32 -> 27 | K32: =IF(I32>0,F32,"") -> 3
A33: STEM | B33: 11-1 | C33: Specialized | D33: General Biology 1 | E33: Sciences | F33: 3 | G33: =SUM(F33:F33) -> 3 | H33: 9 | I33: =H33*G33 -> 27 | K33: =IF(I33>0,F33,"") -> 3
A34: STEM | B34: 11-1 | D34: Homeroom | F34: 1 | G34: =SUM(F34:F34) -> 1 | H34: 9 | I34: =H34*G34 -> 9 | K34: =IF(I34>0,F34,"") -> 1
A35: STEM | B35: 11-1 | D35: Student Club and Org | F35: 1 | G35: =SUM(F35:F35) -> 1 | H35: 9 | I35: =H35*G35 -> 9 | K35: =IF(I35>0,F35,"") -> 1
K36: =IF(I36>0,F36,"")
A37: STEM | B37: 12-1 | C37: Core | D37: Personal Development | E37: Social and Behavioral Sciences | F37: 3 | G37: =SUM(F37:F37) -> 3 | H37: 8 | I37: =H37*G37 -> 24 | K37: =IF(I37>0,F37,"") -> 3
A38: STEM | B38: 12-1 | C38: Core | D38: Pagbasa at Pagsusuri ng Iba't Ibang Teksto Tungo sa Pananaliksik | E38: Filipino | F38: 3 | G38: =SUM(F38:F38) -> 3 | H38: ='2 - Section Count Projection'!$G$18 -> 0 | I38: =H38*G38 -> 0 | K38: =IF(I38>0,F38,"")
A39: STEM | B39: 12-1 | C39: Core | D39: Disaster Readiness and Risk Reduction | E39: Social and Behavioral Sciences | F39: 3 | G39: =SUM(F39:F39) -> 3 | H39: 8 | I39: =H39*G39 -> 24 | K39: =IF(I39>0,F39,"") -> 3
A40: STEM | B40: 12-1 | C40: Core | D40: Physical Education and Health 3 | E40: Physical Education | F40: 3 | G40: =SUM(F40:F40) -> 3 | H40: 8 | I40: =H40*G40 -> 24 | K40: =IF(I40>0,F40,"") -> 3
A41: STEM | B41: 12-1 | C41: Applied | D41: Practical Research 2 | F41: 3 | G41: =SUM(F41:F41) -> 3 | H41: 8 | I41: =H41*G41 -> 24 | K41: =IF(I41>0,F41,"") -> 3
...

Sheet 3.4 - SHS Term 2
A2: Strand/Track | B2: Grade Level Term | C2: Subject Classification | D2: Subject Title | E2: Field of Specialization | F2: LEC | G2: TOTAL | H2: Section Count | I2: Teaching Load
A3: ABM | B3: 11-2 | C3: Core | D3: Reading and Writing | E3: English | F3: 3 | G3: =SUM(F3:F3) -> 3 | H3: 0 | I3: =H3*G3 -> 0 | K3: =IF(I3>0,F3,"")
A4: ABM | B4: 11-2 | C4: Core | D4: Statistics and Probability | E4: Mathematics | F4: 3 | G4: =SUM(F4:F4) -> 3 | H4: 0 | I4: =H4*G4 -> 0 | K4: =IF(I4>0,F4,"")
A5: ABM | B5: 11-2 | C5: Core | D5: Understanding Culture, Society and Politics | E5: Social and Behavioral Sciences | F5: 3 | G5: =SUM(F5:F5) -> 3 | H5: 0 | I5: =H5*G5 -> 0 | K5: =IF(I5>0,F5,"")
A6: ABM | B6: 11-2 | C6: Core | D6: Earth and Life Science | E6: Sciences | F6: 3 | G6: =SUM(F6:F6) -> 3 | H6: 0 | I6: =H6*G6 -> 0 | K6: =IF(I6>0,F6,"")
A7: ABM | B7: 11-2 | C7: Core | D7: Komunikasyon at Pananaliksik sa Wika at Kulturang Pilipino | E7: Filipino | F7: 3 | G7: =SUM(F7:F7) -> 3 | H7: 0 | I7: =H7*G7 -> 0 | K7: =IF(I7>0,F7,"")
A8: ABM | B8: 11-2 | C8: Core | D8: Physical Education and Health 2 | E8: Physical Education | F8: 2 | G8: =SUM(F8:F8) -> 2 | H8: 0 | I8: =H8*G8 -> 0 | K8: =IF(I8>0,F8,"")
A9: ABM | B9: 11-2 | C9: Applied | D9: Practical Research 1 | F9: 3 | G9: =SUM(F9:F9) -> 3 | H9: 0 | I9: =H9*G9 -> 0 | K9: =IF(I9>0,F9,"")
A10: ABM | B10: 11-2 | C10: Specialized | D10: Principles of Marketing | E10: Business and Management | F10: 3 | G10: =SUM(F10:F10) -> 3 | H10: 0 | I10: =H10*G10 -> 0 | K10: =IF(I10>0,F10,"")
A11: ABM | B11: 11-2 | C11: Specialized | D11: Fundamentals of Accountancy, Business and Management 1 | E11: Business and Management | F11: 3 | G11: =SUM(F11:F11) -> 3 | H11: 0 | I11: =H11*G11 -> 0 | K11: =IF(I11>0,F11,"")
A12: ABM | B12: 11-2 | D12: Homeroom | F12: 1 | G12: =SUM(F12:F12) -> 1 | H12: 0 | I12: =H12*G12 -> 0 | K12: =IF(I12>0,F12,"")
A13: ABM | B13: 11-2 | D13: Student Club and Org | E13: Filipino | F13: 1 | G13: =SUM(F13:F13) -> 1 | H13: 0 | I13: =H13*G13 -> 0 | K13: =IF(I13>0,F13,"")
K14: =IF(I14>0,F14,"")
A15: ABM | B15: 12-2 | C15: Core | D15: Contemporary Philippine Arts from the Regions | E15: Social and Behavioral Sciences | F15: 3 | G15: =SUM(F15:F15) -> 3 | H15: 0 | I15: =H15*G15 -> 0 | K15: =IF(I15>0,F15,"")
A16: ABM | B16: 12-2 | C16: Core | D16: Physical Education and Health 4 | E16: Physical Education | F16: 2 | G16: =SUM(F16:F16) -> 2 | H16: 0 | I16: =H16*G16 -> 0 | K16: =IF(I16>0,F16,"")
A17: ABM | B17: 12-2 | C17: Applied | D17: Empowerment Technologies | E17: Information Technology | F17: 3 | G17: =SUM(F17:F17) -> 3 | H17: 0 | I17: =H17*G17 -> 0 | K17: =IF(I17>0,F17,"")
A18: ABM | B18: 12-2 | C18: Applied | D18: Entrepreneurship | E18: Business and Management | F18: 3 | G18: =SUM(F18:F18) -> 3 | H18: 0 | I18: =H18*G18 -> 0 | K18: =IF(I18>0,F18,"")
A19: ABM | B19: 12-2 | C19: Applied | D19: Inquiries, Investigations and Immersion | F19: 3 | G19: =SUM(F19:F19) -> 3 | H19: 0 | I19: =H19*G19 -> 0 | K19: =IF(I19>0,F19,"")
A20: ABM | B20: 12-2 | C20: Specialized | D20: Work Immersion/Research/Career Advocacy/Culminating Activity (Business Enterprise Simulation) | F20: 2 | G20: =SUM(F20:F20) -> 2 | H20: 0 | I20: =H20*G20 -> 0 | K20: =IF(I20>0,F20,"")
A21: ABM | B21: 12-2 | C21: Specialized | D21: Applied Economics | E21: Business and Management | F21: 3 | G21: =SUM(F21:F21) -> 3 | H21: 0 | I21: =H21*G21 -> 0 | K21: =IF(I21>0,F21,"")
A22: ABM | B22: 12-2 | C22: Specialized | D22: Business Ethics and Social Responsibility | E22: Business and Management | F22: 3 | G22: =SUM(F22:F22) -> 3 | H22: 0 | I22: =H22*G22 -> 0 | K22: =IF(I22>0,F22,"")
A23: ABM | B23: 12-2 | D23: Homeroom | F23: 1 | G23: =SUM(F23:F23) -> 1 | H23: 0 | I23: =H23*G23 -> 0 | K23: =IF(I23>0,F23,"")
A24: ABM | B24: 12-2 | D24: Student Club and Org | F24: 1 | G24: =SUM(F24:F24) -> 1 | H24: 0 | I24: =H24*G24 -> 0 | K24: =IF(I24>0,F24,"")
K25: =IF(I25>0,F25,"")
A26: STEM | B26: 11-2 | C26: Core | D26: Reading and Writing | E26: English | F26: 3 | G26: =SUM(F26:F26) -> 3 | H26: 0 | I26: =H26*G26 -> 0 | K26: =IF(I26>0,F26,"")
A27: STEM | B27: 11-2 | C27: Core | D27: Statistics and Probability | E27: Mathematics | F27: 3 | G27: =SUM(F27:F27) -> 3 | H27: 0 | I27: =H27*G27 -> 0 | K27: =IF(I27>0,F27,"")
A28: STEM | B28: 11-2 | C28: Core | D28: Understanding Culture, Society and Politics | E28: Social and Behavioral Sciences | F28: 3 | G28: =SUM(F28:F28) -> 3 | H28: 0 | I28: =H28*G28 -> 0 | K28: =IF(I28>0,F28,"")
A29: STEM | B29: 11-2 | C29: Core | D29: Earth Science | E29: Sciences | F29: 3 | G29: =SUM(F29:F29) -> 3 | H29: 0 | I29: =H29*G29 -> 0 | K29: =IF(I29>0,F29,"")
A30: STEM | B30: 11-2 | C30: Core | D30: Komunikasyon at Pananaliksik sa Wika at Kulturang Pilipino | E30: Filipino | F30: 3 | G30: =SUM(F30:F30) -> 3 | H30: 0 | I30: =H30*G30 -> 0 | K30: =IF(I30>0,F30,"")
A31: STEM | B31: 11-2 | C31: Core | D31: Physical Education and Health 2 | E31: Physical Education | F31: 2 | G31: =SUM(F31:F31) -> 2 | H31: 0 | I31: =H31*G31 -> 0 | K31: =IF(I31>0,F31,"")
A32: STEM | B32: 11-2 | C32: Applied | D32: Practical Research 1 | F32: 3 | G32: =SUM(F32:F32) -> 3 | H32: 0 | I32: =H32*G32 -> 0 | K32: =IF(I32>0,F32,"")
A33: STEM | B33: 11-2 | C33: Specialized | D33: Basic Calculus | E33: Mathematics | F33: 3 | G33: =SUM(F33:F33) -> 3 | H33: 0 | I33: =H33*G33 -> 0 | K33: =IF(I33>0,F33,"")
A34: STEM | B34: 11-2 | C34: Specialized | D34: General Biology 2 | E34: Sciences | F34: 3 | G34: =SUM(F34:F34) -> 3 | H34: 0 | I34: =H34*G34 -> 0 | K34: =IF(I34>0,F34,"")
A35: STEM | B35: 11-2 | D35: Homeroom | F35: 1 | G35: =SUM(F35:F35) -> 1 | H35: 0 | I35: =H35*G35 -> 0 | K35: =IF(I35>0,F35,"")
A36: STEM | B36: 11-2 | D36: Student Club and Org | F36: 1 | G36: =SUM(F36:F36) -> 1 | H36: 9 | I36: =H36*G36 -> 9 | K36: =IF(I36>0,F36,"") -> 1
K37: =IF(I37>0,F37,"")
A38: STEM | B38: 12-2 | C38: Core | D38: Contemporary Philippine Arts from the Regions | E38: Social and Behavioral Sciences | F38: 3 | G38: =SUM(F38:F38) -> 3 | H38: 0 | I38: =H38*G38 -> 0 | K38: =IF(I38>0,F38,"")
A39: STEM | B39: 12-2 | C39: Core | D39: Physical Education and Health 4 | E39: Physical Education | F39: 2 | G39: =SUM(F39:F39) -> 2 | H39: 0 | I39: =H39*G39 -> 0 | K39: =IF(I39>0,F39,"")
A40: STEM | B40: 12-2 | C40: Applied | D40: Empowerment Technologies | E40: Information Technology | F40: 3 | G40: =SUM(F40:F40) -> 3 | H40: 0 | I40: =H40*G40 -> 0 | K40: =IF(I40>0,F40,"")
A41: STEM | B41: 12-2 | C41: Applied | D41: Entrepreneurship | E41: Business and Management | F41: 3 | G41: =SUM(F41:F41) -> 3 | H41: 0 | I41: =H41*G41 -> 0 | K41: =IF(I41>0,F41,"")
...

Sheet Faculty Count Projection
B1: =_xlfn.CONCAT("STI College ",'1 - Top Sheet'!D6:E6) -> STI College Novaliches
B2: Projected Faculty Count
B3: =_xlfn.CONCAT("School Year ",'1 - Top Sheet'!D7:E7," Term ", '1 - Top Sheet'!D8:E8) -> School Year 2024-2025 Term 1
B5: Tertiary Level | H5: High School Level
B7: Field of Specialization | C7: Teaching Load Term 1 | D7: Teaching Load Term 2 | E7: Fulltime FM 24 units | F7: Excess Units | H7: Field of Specialization | I7: Teaching Load Term 1 | J7: Teaching Load Term 2 | K7: Fulltime FM | L7: Excess Units
F8: For PT or Overload | K8: 27 units | L8: For PT or Overload
B9: Accounting | C9: =SUMIF(TER1FIELD,$B9,TER1LOAD) -> 28.5 | D9: =SUMIF(TER2FIELD,$B9,TER2LOAD) -> 0 | E9: =ROUNDDOWN((C9+D9)/24,0) -> 1 | F9: =(C9+D9)-(24*E9) -> 4.5 | H9: Business and Management | I9: =SUMIF(SHS1FIELD,$H9,SHS1LOAD) -> 39 | J9: =SUMIF(SHS2FIELD,$H9,SHS2LOAD) -> 0 | K9: =ROUNDDOWN((I9+J9)/27,0) -> 1 | L9: =(I9+J9)-(27*K9) -> 12
B10: Biological Sciences | C10: =SUMIF(TER1FIELD,$B10,TER1LOAD) -> 0 | D10: =SUMIF(TER2FIELD,$B10,TER2LOAD) -> 0 | E10: =ROUNDDOWN((C10+D10)/24,0) -> 0 | F10: =(C10+D10)-(24*E10) -> 0 | H10: Electrical/Electronics | I10: =SUMIF(SHS1FIELD,$H10,SHS1LOAD) -> 0 | J10: =SUMIF(SHS2FIELD,$H10,SHS2LOAD) -> 0 | K10: =ROUNDDOWN((I10+J10)/27,0) -> 0 | L10: =(I10+J10)-(27*K10) -> 0
B11: Business and Management | C11: =SUMIF(TER1FIELD,$B11,TER1LOAD) -> 0 | D11: =SUMIF(TER2FIELD,$B11,TER2LOAD) -> 0 | E11: =ROUNDDOWN((C11+D11)/24,0) -> 0 | F11: =(C11+D11)-(24*E11) -> 0 | H11: English | I11: =SUMIF(SHS1FIELD,$H11,SHS1LOAD) -> 168 | J11: =SUMIF(SHS2FIELD,$H11,SHS2LOAD) -> 0 | K11: =ROUNDDOWN((I11+J11)/27,0) -> 6 | L11: =(I11+J11)-(27*K11) -> 6
B12: Chemistry | C12: =SUMIF(TER1FIELD,$B12,TER1LOAD) -> 0 | D12: =SUMIF(TER2FIELD,$B12,TER2LOAD) -> 0 | E12: =ROUNDDOWN((C12+D12)/24,0) -> 0 | F12: =(C12+D12)-(24*E12) -> 0 | H12: Filipino | I12: =SUMIF(SHS1FIELD,$H12,SHS1LOAD) -> 102 | J12: =SUMIF(SHS2FIELD,$H12,SHS2LOAD) -> 0 | K12: =ROUNDDOWN((I12+J12)/27,0) -> 3 | L12: =(I12+J12)-(27*K12) -> 21
B13: Communications | C13: =SUMIF(TER1FIELD,$B13,TER1LOAD) -> 0 | D13: =SUMIF(TER2FIELD,$B13,TER2LOAD) -> 0 | E13: =ROUNDDOWN((C13+D13)/24,0) -> 0 | F13: =(C13+D13)-(24*E13) -> 0 | H13: Hospitality/Culinary Mgt | I13: =SUMIF(SHS1FIELD,$H13,SHS1LOAD) -> 24 | J13: =SUMIF(SHS2FIELD,$H13,SHS2LOAD) -> 0 | K13: =ROUNDDOWN((I13+J13)/27,0) -> 0 | L13: =(I13+J13)-(27*K13) -> 24
B14: Computer Graphics | C14: =SUMIF(TER1FIELD,$B14,TER1LOAD) -> 0 | D14: =SUMIF(TER2FIELD,$B14,TER2LOAD) -> 0 | E14: =ROUNDDOWN((C14+D14)/24,0) -> 0 | F14: =(C14+D14)-(24*E14) -> 0 | H14: Information Technology | I14: =SUMIF(SHS1FIELD,$H14,SHS1LOAD) -> 36 | J14: =SUMIF(SHS2FIELD,$H14,SHS2LOAD) -> 0 | K14: =ROUNDDOWN((I14+J14)/27,0) -> 1 | L14: =(I14+J14)-(27*K14) -> 9
B15: Criminology | C15: =SUMIF(TER1FIELD,$B15,TER1LOAD) -> 0 | D15: =SUMIF(TER2FIELD,$B15,TER2LOAD) -> 0 | E15: =ROUNDDOWN((C15+D15)/24,0) -> 0 | F15: =(C15+D15)-(24*E15) -> 0 | H15: Mathematics | I15: =SUMIF(SHS1FIELD,$H15,SHS1LOAD) -> 93 | J15: =SUMIF(SHS2FIELD,$H15,SHS2LOAD) -> 0 | K15: =ROUNDDOWN((I15+J15)/27,0) -> 3 | L15: =(I15+J15)-(27*K15) -> 12
B16: Engineering | C16: =SUMIF(TER1FIELD,$B16,TER1LOAD) -> 62 | D16: =SUMIF(TER2FIELD,$B16,TER2LOAD) -> 0 | E16: =ROUNDDOWN((C16+D16)/24,0) -> 2 | F16: =(C16+D16)-(24*E16) -> 14 | H16: Physical Education | I16: =SUMIF(SHS1FIELD,$H16,SHS1LOAD) -> 129 | J16: =SUMIF(SHS2FIELD,$H16,SHS2LOAD) -> 0 | K16: =ROUNDDOWN((I16+J16)/27,0) -> 4 | L16: =(I16+J16)-(27*K16) -> 21
B17: English/Foreign Language | C17: =SUMIF(TER1FIELD,$B17,TER1LOAD) -> 84 | D17: =SUMIF(TER2FIELD,$B17,TER2LOAD) -> 0 | E17: =ROUNDDOWN((C17+D17)/24,0) -> 3 | F17: =(C17+D17)-(24*E17) -> 12 | H17: Sciences | I17: =SUMIF(SHS1FIELD,$H17,SHS1LOAD) -> 114 | J17: =SUMIF(SHS2FIELD,$H17,SHS2LOAD) -> 0 | K17: =ROUNDDOWN((I17+J17)/27,0) -> 4 | L17: =(I17+J17)-(27*K17) -> 6
B18: Filipino | C18: =SUMIF(TER1FIELD,$B18,TER1LOAD) -> 0 | D18: =SUMIF(TER2FIELD,$B18,TER2LOAD) -> 0 | E18: =ROUNDDOWN((C18+D18)/24,0) -> 0 | F18: =(C18+D18)-(24*E18) -> 0 | H18: Social and Behavioral Sciences | I18: =SUMIF(SHS1FIELD,$H18,SHS1LOAD) -> 207 | J18: =SUMIF(SHS2FIELD,$H18,SHS2LOAD) -> 0 | K18: =ROUNDDOWN((I18+J18)/27,0) -> 7 | L18: =(I18+J18)-(27*K18) -> 18
B19: Hospitality/Culinary Mgt | C19: =SUMIF(TER1FIELD,$B19,TER1LOAD) -> 89 | D19: =SUMIF(TER2FIELD,$B19,TER2LOAD) -> 0 | E19: =ROUNDDOWN((C19+D19)/24,0) -> 3 | F19: =(C19+D19)-(24*E19) -> 17 | H19: Tourism Management | I19: =SUMIF(SHS1FIELD,$H19,SHS1LOAD) -> 24 | J19: =SUMIF(SHS2FIELD,$H19,SHS2LOAD) -> 0 | K19: =ROUNDDOWN((I19+J19)/27,0) -> 0 | L19: =(I19+J19)-(27*K19) -> 24
B20: Information Technology | C20: =SUMIF(TER1FIELD,$B20,TER1LOAD) -> 340.5 | D20: =SUMIF(TER2FIELD,$B20,TER2LOAD) -> 0 | E20: =ROUNDDOWN((C20+D20)/24,0) -> 14 | F20: =(C20+D20)-(24*E20) -> 4.5
B21: Law | C21: =SUMIF(TER1FIELD,$B21,TER1LOAD) -> 0 | D21: =SUMIF(TER2FIELD,$B21,TER2LOAD) -> 0 | E21: =ROUNDDOWN((C21+D21)/24,0) -> 0 | F21: =(C21+D21)-(24*E21) -> 0
B22: Mathematics | C22: =SUMIF(TER1FIELD,$B22,TER1LOAD) -> 51 | D22: =SUMIF(TER2FIELD,$B22,TER2LOAD) -> 0 | E22: =ROUNDDOWN((C22+D22)/24,0) -> 2 | F22: =(C22+D22)-(24*E22) -> 3
B23: Multimedia Arts | C23: =SUMIF(TER1FIELD,$B23,TER1LOAD) -> 153.5 | D23: =SUMIF(TER2FIELD,$B23,TER2LOAD) -> 0 | E23: =ROUNDDOWN((C23+D23)/24,0) -> 6 | F23: =(C23+D23)-(24*E23) -> 9.5
B24: Philosophy | C24: =SUMIF(TER1FIELD,$B24,TER1LOAD) -> 0 | D24: =SUMIF(TER2FIELD,$B24,TER2LOAD) -> 0 | E24: =ROUNDDOWN((C24+D24)/24,0) -> 0 | F24: =(C24+D24)-(24*E24) -> 0
B25: Physical Education | C25: =SUMIF(TER1FIELD,$B25,TER1LOAD) -> 92 | D25: =SUMIF(TER2FIELD,$B25,TER2LOAD) -> 0 | E25: =ROUNDDOWN((C25+D25)/24,0) -> 3 | F25: =(C25+D25)-(24*E25) -> 20
B26: Physical Sciences | C26: =SUMIF(TER1FIELD,$B26,TER1LOAD) -> 0 | D26: =SUMIF(TER2FIELD,$B26,TER2LOAD) -> 0 | E26: =ROUNDDOWN((C26+D26)/24,0) -> 0 | F26: =(C26+D26)-(24*E26) -> 0
B27: Psychology | C27: =SUMIF(TER1FIELD,$B27,TER1LOAD) -> 0 | D27: =SUMIF(TER2FIELD,$B27,TER2LOAD) -> 0 | E27: =ROUNDDOWN((C27+D27)/24,0) -> 0 | F27: =(C27+D27)-(24*E27) -> 0
B28: Social and Behavioral Science | C28: =SUMIF(TER1FIELD,$B28,TER1LOAD) -> 162 | D28: =SUMIF(TER2FIELD,$B28,TER2LOAD) -> 0 | E28: =ROUNDDOWN((C28+D28)/24,0) -> 6 | F28: =(C28+D28)-(24*E28) -> 18
B29: Tourism Management | C29: =SUMIF(TER1FIELD,$B29,TER1LOAD) -> 25 | D29: =SUMIF(TER2FIELD,$B29,TER2LOAD) -> 0 | E29: =ROUNDDOWN((C29+D29)/24,0) -> 1 | F29: =(C29+D29)-(24*E29) -> 1

Sheet 4.2 - SHS Schedule
A1: =_xlfn.CONCAT("STI College ",'1 - Top Sheet'!C6:D6) -> STI College Novaliches
A2: SHS Schedule
A3: =_xlfn.CONCAT("School Year ",'1 - Top Sheet'!C7:D7," Term ", '1 - Top Sheet'!C8:D8) -> School Year 2024-2025 Term 1
A5: SECTION | B5: SUBJECT CODE | C5: SUBJECT DESCRIPTION | D5: DAY | E5: TIME | H5: ROOM | I5: TEACHER
A6: ABM101 | C6: 21st Century Literature | D6: M/TH | E6: 0.29166667 | G6: 0.35416667 | H6: 501 | I6: Mark Joseph Tan
C7: General Mathematics | D7: M/TH | E7: 0.35416667 | G7: 0.41666667 | H7: 501 | I7: John Paul Cabanero
C8: Intro to the Philo of Human | D8: M/TH | E8: 0.47916667 | G8: 0.54166667 | H8: 501 | I8: Elvira Sigua
C9: Business Mathematics | D9: T/F | E9: 0.29166667 | G9: 0.35416667 | H9: 501 | I9: Math PTFL
C10: Oral Communication | D10: T/F | E10: 0.35416667 | G10: 0.41666667 | H10: 501 | I10: Mark Joseph Tan
C11: Physical Education & Health 1 | D11: T/F | E11: 0.47916667 | G11: 0.54166667 | H11: COURT | I11: Mary Rose Batan
C12: Homeroom G11-1st Term | D12: M | E12: 0.54166667 | G12: 0.58333333
C13: Organization & Management | D13: W | E13: 0.29166667 | G13: 0.41666667 | H13: 501 | I13: Joshua Uclusin
C14: Media and Information Literarcy | D14: W | E14: 0.47916667 | G14: 0.60416667 | H14: 501 | I14: Aiza Mae Akkang
A19: SECTION | B19: SUBJECT CODE | C19: SUBJECT DESCRIPTION | D19: DAY | E19: TIME | H19: ROOM | I19: TEACHER
A20: ABM102 | C20: 21st Century Literature | D20: M/TH | E20: 0.35416667 | G20: 0.41666667 | H20: 502
C21: General Mathematics | D21: M/TH | E21: 0.41666667 | G21: 0.97916667 | H21: 502
C22: Intro to the Philo of Human | D22: M/TH | E22: 0.54166667 | G22: 0.60416667 | H22: 502
C23: Oral Communication | D23: T/F | E23: 0.35416667 | G23: 0.41666667 | H23: 502
C24: Organization & Management | D24: T/F | E24: 0.41666667 | G24: 0.97916667 | H24: 502
C25: Media and Information Literarcy | D25: T/F | E25: 0.54166667 | G25: 0.60416667 | H25: 502
C26: Business Mathematics | D26: W | E26: 0.29166667 | G26: 0.41666667 | H26: 502
C27: Homeroom G11-1st Term | D27: W | E27: 0.5625 | G27: 0.60416667
C28: Business Mathematics | D28: W | E28: 0.29166667 | G28: 0.41666667 | H28: 502
C29: Physical Education & Health 1 | D29: W | E29: 0.47916667 | G29: 0.5625 | H29: COURT
A33: SECTION | B33: SUBJECT CODE | C33: SUBJECT DESCRIPTION | D33: DAY | E33: TIME | H33: ROOM | I33: TEACHER
A34: ABM103 | C34: 21st Century Literature | D34: M/TH | E34: 0.35416667 | G34: 0.41666667 | H34: 503 | I34: Mark Joseph Tan
C35: General Mathematics | D35: M/TH | E35: 0.47916667 | G35: 0.54166667 | H35: 503 | I35: John Paul Cabanero
C36: Intro to the Philo of Human | D36: T/F | E36: 0.29166667 | G36: 0.35416667 | H36: 503 | I36: Elvira Sigua
C37: Oral Communication | D37: T/F | E37: 0.47916667 | G37: 0.54166667 | H37: 503 | I37: English PTFL
C38: Organization & Management | D38: W | E38: 0.47916667 | G38: 0.60416667 | H38: 303 | I38: Joshua Uclusin
C39: Media and Information Literarcy | D39: T/F | E39: 0.35416667 | G39: 0.41666667 | H39: 503 | I39: Aiza Mae Akkang
C40: Business Mathematics | D40: M/TH | E40: 0.29166667 | G40: 0.35416667 | H40: 503 | I40: Math PTFL
C41: Homeroom G11-1st Term | D41: W | E41: 0.60416667 | G41: 0.64583333
C42: Physical Education & Health 1 | D42: W | E42: 0.33333333 | G42: 0.41666667 | H42: COURT | I42: Mary Rose Batan
A47: SECTION | B47: SUBJECT CODE | C47: SUBJECT DESCRIPTION | D47: DAY | E47: TIME | H47: ROOM | I47: TEACHER
A48: CULART101 | C48: 21st Century Literature | D48: M/TH | E48: 0.47916667 | G48: 0.54166667 | H48: 504 | I48: Evelyn Quarteros
C49: Oral Communication | D49: T/F | E49: 0.54166667 | G49: 0.60416667 | H49: 504
C50: Media and Information Literacy | D50: T/F | E50: 0.41666667 | G50: 0.47916667 | H50: 504 | I50: Aiza Mae Akkang
C51: Intro to the Philo of Human | D51: T/F | E51: 0.35416667 | G51: 0.41666667 | H51: 504 | I51: Elvira Sigua
C52: General Mathematics | D52: M/TH | E52: 0.54166667 | G52: 0.60416667 | H52: 504 | I52: John Paul Cabanero
...

Sheet 4.1 - TER Schedule
A1: =_xlfn.CONCAT("STI College ",'1 - Top Sheet'!C6:D6) -> STI College Novaliches
A2: Tertiary Schedule
A3: =_xlfn.CONCAT("School Year ",'1 - Top Sheet'!C7:D7," Term ", '1 - Top Sheet'!C8:D8) -> School Year 2024-2025 Term 1
A5: SECTION | B5: COURSE CODE | C5: COURSE DESCRIPTION | D5: DAY | E5: TIME | H5: ROOM | I5: INSTRUCTOR
A6: BT101 | B6: CITE1004 | C6: Introduction to Computing | D6: TF | E6: 4:00PM | G6: 6:00PM | H6: 203/LAB209 | I6: ITFT1
B7: CITE1003 | C7: Computer Programming 1 | D7: M | E7: 0.33333333 | G7: 0.41666667 | H7: 201 | I7: Eugene
B8: CITE1003 | C8: Computer Programming 1 | D8: M | E8: 0.41666667 | G8: 0.54166667 | H8: LAB210 | I8: Eugene
B9: GEDC1002 | C9: The Contemporary World | D9: S | E9: 12:30PM | G9: 3:30PM | H9: 306 | I9: SOC SCI FT4
B10: STIC1002 | C10: Euthenics 1 | D10: S | E10: 3:30PM | G10: 4:30PM | H10: 306 | I10: SOC SCI FT4
B11: GEDC1016 | C11: Purposive Communication | D11: MTH | E11: 0.60416667 | G11: 0.66666667 | H11: 301 | I11: BONCAN
B12: NSTP1008 | C12: National Service Training Program 1 | D12: TF | E12: 0.54166667 | G12: 0.60416667 | H12: 302 | I12: PALMERO
B13: PHED1005 | C13: P.E./PATHFIT 1: Movement Competency Training | D13: TH | E13: 0.5 | G13: 0.58333333 | H13: COURT | I13: SABORIENDO-GARCIA
B14: GEDC1041 | C14: Philippine Popular Culture | D14: TF | E14: 0.60416667 | G14: 0.66666667 | H14: 407 | I14: SOC SCI FT2
B15: GEDC1008 | C15: Understanding the Self | D15: MTH | E15: 0.60416667 | G15: 0.66666667 | H15: 301 | I15: BONCAN
A19: SECTION | B19: COURSE CODE | C19: COURSE DESCRIPTION | D19: DAY | E19: TIME | H19: ROOM | I19: INSTRUCTOR
A20: BT102 | B20: CITE1004 | C20: Introduction to Computing | D20: F | E20: 0.5 | G20: 2:00PM | H20: 207/LAB211 | I20: AGUILA
B21: CITE1003 | C21: Computer Programming 1 | D21: T | E21: 0.33333333 | G21: 0.41666667 | H21: 201 | I21: RESULLAR
B22: CITE1003 | C22: Computer Programming 1 | D22: T | E22: 0.41666667 | G22: 0.54166667 | H22: LAB210 | I22: RESULLAR
B23: GEDC1002 | C23: The Contemporary World | D23: MTH | E23: 0.35416667 | G23: 0.41666667 | H23: 302 | I23: SOC SCI FT4
B24: STIC1002 | C24: Euthenics 1 | D24: MTH | E24: 0.66666667 | G24: 0.70833333 | H24: 204 | I24: ROSALES
